Workbook

Sheet Buscador rápido
A1: FLOKI · BUSCADOR RÁPIDO DE PERSONAS
A2: Evento: Floki Night | B2: Fecha: 2026-08-01 | C2: Generado: 01/08/2026 01:09
A3: Escribí un nombre
A4: El buscador muestra coincidencias de todas las listas: promotores, cumpleaños, PROMOS y Lista común.
A6: Nombre | B6: Lista / promotor | C6: Tipo | D6: Estado | E6: Ingreso | F6: Nacimiento | G6: Detalle | H6: #
A7: =IF($H7="","",IFERROR(INDEX(Personas!$A$2:$A$1001,$H7),"")) | B7: =IF($H7="","",IFERROR(INDEX(Personas!$B$2:$B$1001,$H7),"")) | C7: =IF($H7="","",IFERROR(INDEX(Personas!$C$2:$C$1001,$H7),"")) | D7: =IF($H7="","",IFERROR(INDEX(Personas!$D$2:$D$1001,$H7),"")) | E7: =IF($H7="","",IFERROR(INDEX(Personas!$E$2:$E$1001,$H7),"")) | F7: =IF($H7="","",IFERROR(INDEX(Personas!$F$2:$F$1001,$H7),"")) | G7: =IF($H7="","",IFERROR(INDEX(Personas!$G$2:$G$1001,$H7),"")) | H7: =IF($B$3="","",IFERROR(AGGREGATE(15,6,(ROW(Personas!$H$2:$H$1001)-ROW(Personas!$H$2)+1)/(ISNUMBER(SEARCH($B$3,Personas!$H$2:$H$1001))),1),""))
A8: =IF($H8="","",IFERROR(INDEX(Personas!$A$2:$A$1001,$H8),"")) | B8: =IF($H8="","",IFERROR(INDEX(Personas!$B$2:$B$1001,$H8),"")) | C8: =IF($H8="","",IFERROR(INDEX(Personas!$C$2:$C$1001,$H8),"")) | D8: =IF($H8="","",IFERROR(INDEX(Personas!$D$2:$D$1001,$H8),"")) | E8: =IF($H8="","",IFERROR(INDEX(Personas!$E$2:$E$1001,$H8),"")) | F8: =IF($H8="","",IFERROR(INDEX(Personas!$F$2:$F$1001,$H8),"")) | G8: =IF($H8="","",IFERROR(INDEX(Personas!$G$2:$G$1001,$H8),"")) | H8: =IF($B$3="","",IFERROR(AGGREGATE(15,6,(ROW(Personas!$H$2:$H$1001)-ROW(Personas!$H$2)+1)/(ISNUMBER(SEARCH($B$3,Personas!$H$2:$H$1001))),2),""))
A9: =IF($H9="","",IFERROR(INDEX(Personas!$A$2:$A$1001,$H9),"")) | B9: =IF($H9="","",IFERROR(INDEX(Personas!$B$2:$B$1001,$H9),"")) | C9: =IF($H9="","",IFERROR(INDEX(Personas!$C$2:$C$1001,$H9),"")) | D9: =IF($H9="","",IFERROR(INDEX(Personas!$D$2:$D$1001,$H9),"")) | E9: =IF($H9="","",IFERROR(INDEX(Personas!$E$2:$E$1001,$H9),"")) | F9: =IF($H9="","",IFERROR(INDEX(Personas!$F$2:$F$1001,$H9),"")) | G9: =IF($H9="","",IFERROR(INDEX(Personas!$G$2:$G$1001,$H9),"")) | H9: =IF($B$3="","",IFERROR(AGGREGATE(15,6,(ROW(Personas!$H$2:$H$1001)-ROW(Personas!$H$2)+1)/(ISNUMBER(SEARCH($B$3,Personas!$H$2:$H$1001))),3),""))
A10: =IF($H10="","",IFERROR(INDEX(Personas!$A$2:$A$1001,$H10),"")) | B10: =IF($H10="","",IFERROR(INDEX(Personas!$B$2:$B$1001,$H10),"")) | C10: =IF($H10="","",IFERROR(INDEX(Personas!$C$2:$C$1001,$H10),"")) | D10: =IF($H10="","",IFERROR(INDEX(Personas!$D$2:$D$1001,$H10),"")) | E10: =IF($H10="","",IFERROR(INDEX(Personas!$E$2:$E$1001,$H10),"")) | F10: =IF($H10="","",IFERROR(INDEX(Personas!$F$2:$F$1001,$H10),"")) | G10: =IF($H10="","",IFERROR(INDEX(Personas!$G$2:$G$1001,$H10),"")) | H10: =IF($B$3="","",IFERROR(AGGREGATE(15,6,(ROW(Personas!$H$2:$H$1001)-ROW(Personas!$H$2)+1)/(ISNUMBER(SEARCH($B$3,Personas!$H$2:$H$1001))),4),""))
A11: =IF($H11="","",IFERROR(INDEX(Personas!$A$2:$A$1001,$H11),"")) | B11: =IF($H11="","",IFERROR(INDEX(Personas!$B$2:$B$1001,$H11),"")) | C11: =IF($H11="","",IFERROR(INDEX(Personas!$C$2:$C$1001,$H11),"")) | D11: =IF($H11="","",IFERROR(INDEX(Personas!$D$2:$D$1001,$H11),"")) | E11: =IF($H11="","",IFERROR(INDEX(Personas!$E$2:$E$1001,$H11),"")) | F11: =IF($H11="","",IFERROR(INDEX(Personas!$F$2:$F$1001,$H11),"")) | G11: =IF($H11="","",IFERROR(INDEX(Personas!$G$2:$G$1001,$H11),"")) | H11: =IF($B$3="","",IFERROR(AGGREGATE(15,6,(ROW(Personas!$H$2:$H$1001)-ROW(Personas!$H$2)+1)/(ISNUMBER(SEARCH($B$3,Personas!$H$2:$H$1001))),5),""))
A12: =IF($H12="","",IFERROR(INDEX(Personas!$A$2:$A$1001,$H12),"")) | B12: =IF($H12="","",IFERROR(INDEX(Personas!$B$2:$B$1001,$H12),"")) | C12: =IF($H12="","",IFERROR(INDEX(Personas!$C$2:$C$1001,$H12),"")) | D12: =IF($H12="","",IFERROR(INDEX(Personas!$D$2:$D$1001,$H12),"")) | E12: =IF($H12="","",IFERROR(INDEX(Personas!$E$2:$E$1001,$H12),"")) | F12: =IF($H12="","",IFERROR(INDEX(Personas!$F$2:$F$1001,$H12),"")) | G12: =IF($H12="","",IFERROR(INDEX(Personas!$G$2:$G$1001,$H12),"")) | H12: =IF($B$3="","",IFERROR(AGGREGATE(15,6,(ROW(Personas!$H$2:$H$1001)-ROW(Personas!$H$2)+1)/(ISNUMBER(SEARCH($B$3,Personas!$H$2:$H$1001))),6),""))
A13: =IF($H13="","",IFERROR(INDEX(Personas!$A$2:$A$1001,$H13),"")) | B13: =IF($H13="","",IFERROR(INDEX(Personas!$B$2:$B$1001,$H13),"")) | C13: =IF($H13="","",IFERROR(INDEX(Personas!$C$2:$C$1001,$H13),"")) | D13: =IF($H13="","",IFERROR(INDEX(Personas!$D$2:$D$1001,$H13),"")) | E13: =IF($H13="","",IFERROR(INDEX(Personas!$E$2:$E$1001,$H13),"")) | F13: =IF($H13="","",IFERROR(INDEX(Personas!$F$2:$F$1001,$H13),"")) | G13: =IF($H13="","",IFERROR(INDEX(Personas!$G$2:$G$1001,$H13),"")) | H13: =IF($B$3="","",IFERROR(AGGREGATE(15,6,(ROW(Personas!$H$2:$H$1001)-ROW(Personas!$H$2)+1)/(ISNUMBER(SEARCH($B$3,Personas!$H$2:$H$1001))),7),""))
A14: =IF($H14="","",IFERROR(INDEX(Personas!$A$2:$A$1001,$H14),"")) | B14: =IF($H14="","",IFERROR(INDEX(Personas!$B$2:$B$1001,$H14),"")) | C14: =IF($H14="","",IFERROR(INDEX(Personas!$C$2:$C$1001,$H14),"")) | D14: =IF($H14="","",IFERROR(INDEX(Personas!$D$2:$D$1001,$H14),"")) | E14: =IF($H14="","",IFERROR(INDEX(Personas!$E$2:$E$1001,$H14),"")) | F14: =IF($H14="","",IFERROR(INDEX(Personas!$F$2:$F$1001,$H14),"")) | G14: =IF($H14="","",IFERROR(INDEX(Personas!$G$2:$G$1001,$H14),"")) | H14: =IF($B$3="","",IFERROR(AGGREGATE(15,6,(ROW(Personas!$H$2:$H$1001)-ROW(Personas!$H$2)+1)/(ISNUMBER(SEARCH($B$3,Personas!$H$2:$H$1001))),8),""))
A15: =IF($H15="","",IFERROR(INDEX(Personas!$A$2:$A$1001,$H15),"")) | B15: =IF($H15="","",IFERROR(INDEX(Personas!$B$2:$B$1001,$H15),"")) | C15: =IF($H15="","",IFERROR(INDEX(Personas!$C$2:$C$1001,$H15),"")) | D15: =IF($H15="","",IFERROR(INDEX(Personas!$D$2:$D$1001,$H15),"")) | E15: =IF($H15="","",IFERROR(INDEX(Personas!$E$2:$E$1001,$H15),"")) | F15: =IF($H15="","",IFERROR(INDEX(Personas!$F$2:$F$1001,$H15),"")) | G15: =IF($H15="","",IFERROR(INDEX(Personas!$G$2:$G$1001,$H15),"")) | H15: =IF($B$3="","",IFERROR(AGGREGATE(15,6,(ROW(Personas!$H$2:$H$1001)-ROW(Personas!$H$2)+1)/(ISNUMBER(SEARCH($B$3,Personas!$H$2:$H$1001))),9),""))
A16: =IF($H16="","",IFERROR(INDEX(Personas!$A$2:$A$1001,$H16),"")) | B16: =IF($H16="","",IFERROR(INDEX(Personas!$B$2:$B$1001,$H16),"")) | C16: =IF($H16="","",IFERROR(INDEX(Personas!$C$2:$C$1001,$H16),"")) | D16: =IF($H16="","",IFERROR(INDEX(Personas!$D$2:$D$1001,$H16),"")) | E16: =IF($H16="","",IFERROR(INDEX(Personas!$E$2:$E$1001,$H16),"")) | F16: =IF($H16="","",IFERROR(INDEX(Personas!$F$2:$F$1001,$H16),"")) | G16: =IF($H16="","",IFERROR(INDEX(Personas!$G$2:$G$1001,$H16),"")) | H16: =IF($B$3="","",IFERROR(AGGREGATE(15,6,(ROW(Personas!$H$2:$H$1001)-ROW(Personas!$H$2)+1)/(ISNUMBER(SEARCH($B$3,Personas!$H$2:$H$1001))),10),""))
A17: =IF($H17="","",IFERROR(INDEX(Personas!$A$2:$A$1001,$H17),"")) | B17: =IF($H17="","",IFERROR(INDEX(Personas!$B$2:$B$1001,$H17),"")) | C17: =IF($H17="","",IFERROR(INDEX(Personas!$C$2:$C$1001,$H17),"")) | D17: =IF($H17="","",IFERROR(INDEX(Personas!$D$2:$D$1001,$H17),"")) | E17: =IF($H17="","",IFERROR(INDEX(Personas!$E$2:$E$1001,$H17),"")) | F17: =IF($H17="","",IFERROR(INDEX(Personas!$F$2:$F$1001,$H17),"")) | G17: =IF($H17="","",IFERROR(INDEX(Personas!$G$2:$G$1001,$H17),"")) | H17: =IF($B$3="","",IFERROR(AGGREGATE(15,6,(ROW(Personas!$H$2:$H$1001)-ROW(Personas!$H$2)+1)/(ISNUMBER(SEARCH($B$3,Personas!$H$2:$H$1001))),11),""))
A18: =IF($H18="","",IFERROR(INDEX(Personas!$A$2:$A$1001,$H18),"")) | B18: =IF($H18="","",IFERROR(INDEX(Personas!$B$2:$B$1001,$H18),"")) | C18: =IF($H18="","",IFERROR(INDEX(Personas!$C$2:$C$1001,$H18),"")) | D18: =IF($H18="","",IFERROR(INDEX(Personas!$D$2:$D$1001,$H18),"")) | E18: =IF($H18="","",IFERROR(INDEX(Personas!$E$2:$E$1001,$H18),"")) | F18: =IF($H18="","",IFERROR(INDEX(Personas!$F$2:$F$1001,$H18),"")) | G18: =IF($H18="","",IFERROR(INDEX(Personas!$G$2:$G$1001,$H18),"")) | H18: =IF($B$3="","",IFERROR(AGGREGATE(15,6,(ROW(Personas!$H$2:$H$1001)-ROW(Personas!$H$2)+1)/(ISNUMBER(SEARCH($B$3,Personas!$H$2:$H$1001))),12),""))
A19: =IF($H19="","",IFERROR(INDEX(Personas!$A$2:$A$1001,$H19),"")) | B19: =IF($H19="","",IFERROR(INDEX(Personas!$B$2:$B$1001,$H19),"")) | C19: =IF($H19="","",IFERROR(INDEX(Personas!$C$2:$C$1001,$H19),"")) | D19: =IF($H19="","",IFERROR(INDEX(Personas!$D$2:$D$1001,$H19),"")) | E19: =IF($H19="","",IFERROR(INDEX(Personas!$E$2:$E$1001,$H19),"")) | F19: =IF($H19="","",IFERROR(INDEX(Personas!$F$2:$F$1001,$H19),"")) | G19: =IF($H19="","",IFERROR(INDEX(Personas!$G$2:$G$1001,$H19),"")) | H19: =IF($B$3="","",IFERROR(AGGREGATE(15,6,(ROW(Personas!$H$2:$H$1001)-ROW(Personas!$H$2)+1)/(ISNUMBER(SEARCH($B$3,Personas!$H$2:$H$1001))),13),""))
A20: =IF($H20="","",IFERROR(INDEX(Personas!$A$2:$A$1001,$H20),"")) | B20: =IF($H20="","",IFERROR(INDEX(Personas!$B$2:$B$1001,$H20),"")) | C20: =IF($H20="","",IFERROR(INDEX(Personas!$C$2:$C$1001,$H20),"")) | D20: =IF($H20="","",IFERROR(INDEX(Personas!$D$2:$D$1001,$H20),"")) | E20: =IF($H20="","",IFERROR(INDEX(Personas!$E$2:$E$1001,$H20),"")) | F20: =IF($H20="","",IFERROR(INDEX(Personas!$F$2:$F$1001,$H20),"")) | G20: =IF($H20="","",IFERROR(INDEX(Personas!$G$2:$G$1001,$H20),"")) | H20: =IF($B$3="","",IFERROR(AGGREGATE(15,6,(ROW(Personas!$H$2:$H$1001)-ROW(Personas!$H$2)+1)/(ISNUMBER(SEARCH($B$3,Personas!$H$2:$H$1001))),14),""))
A21: =IF($H21="","",IFERROR(INDEX(Personas!$A$2:$A$1001,$H21),"")) | B21: =IF($H21="","",IFERROR(INDEX(Personas!$B$2:$B$1001,$H21),"")) | C21: =IF($H21="","",IFERROR(INDEX(Personas!$C$2:$C$1001,$H21),"")) | D21: =IF($H21="","",IFERROR(INDEX(Personas!$D$2:$D$1001,$H21),"")) | E21: =IF($H21="","",IFERROR(INDEX(Personas!$E$2:$E$1001,$H21),"")) | F21: =IF($H21="","",IFERROR(INDEX(Personas!$F$2:$F$1001,$H21),"")) | G21: =IF($H21="","",IFERROR(INDEX(Personas!$G$2:$G$1001,$H21),"")) | H21: =IF($B$3="","",IFERROR(AGGREGATE(15,6,(ROW(Personas!$H$2:$H$1001)-ROW(Personas!$H$2)+1)/(ISNUMBER(SEARCH($B$3,Personas!$H$2:$H$1001))),15),""))
A22: =IF($H22="","",IFERROR(INDEX(Personas!$A$2:$A$1001,$H22),"")) | B22: =IF($H22="","",IFERROR(INDEX(Personas!$B$2:$B$1001,$H22),"")) | C22: =IF($H22="","",IFERROR(INDEX(Personas!$C$2:$C$1001,$H22),"")) | D22: =IF($H22="","",IFERROR(INDEX(Personas!$D$2:$D$1001,$H22),"")) | E22: =IF($H22="","",IFERROR(INDEX(Personas!$E$2:$E$1001,$H22),"")) | F22: =IF($H22="","",IFERROR(INDEX(Personas!$F$2:$F$1001,$H22),"")) | G22: =IF($H22="","",IFERROR(INDEX(Personas!$G$2:$G$1001,$H22),"")) | H22: =IF($B$3="","",IFERROR(AGGREGATE(15,6,(ROW(Personas!$H$2:$H$1001)-ROW(Personas!$H$2)+1)/(ISNUMBER(SEARCH($B$3,Personas!$H$2:$H$1001))),16),""))
A23: =IF($H23="","",IFERROR(INDEX(Personas!$A$2:$A$1001,$H23),"")) | B23: =IF($H23="","",IFERROR(INDEX(Personas!$B$2:$B$1001,$H23),"")) | C23: =IF($H23="","",IFERROR(INDEX(Personas!$C$2:$C$1001,$H23),"")) | D23: =IF($H23="","",IFERROR(INDEX(Personas!$D$2:$D$1001,$H23),"")) | E23: =IF($H23="","",IFERROR(INDEX(Personas!$E$2:$E$1001,$H23),"")) | F23: =IF($H23="","",IFERROR(INDEX(Personas!$F$2:$F$1001,$H23),"")) | G23: =IF($H23="","",IFERROR(INDEX(Personas!$G$2:$G$1001,$H23),"")) | H23: =IF($B$3="","",IFERROR(AGGREGATE(15,6,(ROW(Personas!$H$2:$H$1001)-ROW(Personas!$H$2)+1)/(ISNUMBER(SEARCH($B$3,Personas!$H$2:$H$1001))),17),""))
A24: =IF($H24="","",IFERROR(INDEX(Personas!$A$2:$A$1001,$H24),"")) | B24: =IF($H24="","",IFERROR(INDEX(Personas!$B$2:$B$1001,$H24),"")) | C24: =IF($H24="","",IFERROR(INDEX(Personas!$C$2:$C$1001,$H24),"")) | D24: =IF($H24="","",IFERROR(INDEX(Personas!$D$2:$D$1001,$H24),"")) | E24: =IF($H24="","",IFERROR(INDEX(Personas!$E$2:$E$1001,$H24),"")) | F24: =IF($H24="","",IFERROR(INDEX(Personas!$F$2:$F$1001,$H24),"")) | G24: =IF($H24="","",IFERROR(INDEX(Personas!$G$2:$G$1001,$H24),"")) | H24: =IF($B$3="","",IFERROR(AGGREGATE(15,6,(ROW(Personas!$H$2:$H$1001)-ROW(Personas!$H$2)+1)/(ISNUMBER(SEARCH($B$3,Personas!$H$2:$H$1001))),18),""))
A25: =IF($H25="","",IFERROR(INDEX(Personas!$A$2:$A$1001,$H25),"")) | B25: =IF($H25="","",IFERROR(INDEX(Personas!$B$2:$B$1001,$H25),"")) | C25: =IF($H25="","",IFERROR(INDEX(Personas!$C$2:$C$1001,$H25),"")) | D25: =IF($H25="","",IFERROR(INDEX(Personas!$D$2:$D$1001,$H25),"")) | E25: =IF($H25="","",IFERROR(INDEX(Personas!$E$2:$E$1001,$H25),"")) | F25: =IF($H25="","",IFERROR(INDEX(Personas!$F$2:$F$1001,$H25),"")) | G25: =IF($H25="","",IFERROR(INDEX(Personas!$G$2:$G$1001,$H25),"")) | H25: =IF($B$3="","",IFERROR(AGGREGATE(15,6,(ROW(Personas!$H$2:$H$1001)-ROW(Personas!$H$2)+1)/(ISNUMBER(SEARCH($B$3,Personas!$H$2:$H$1001))),19),""))
A26: =IF($H26="","",IFERROR(INDEX(Personas!$A$2:$A$1001,$H26),"")) | B26: =IF($H26="","",IFERROR(INDEX(Personas!$B$2:$B$1001,$H26),"")) | C26: =IF($H26="","",IFERROR(INDEX(Personas!$C$2:$C$1001,$H26),"")) | D26: =IF($H26="","",IFERROR(INDEX(Personas!$D$2:$D$1001,$H26),"")) | E26: =IF($H26="","",IFERROR(INDEX(Personas!$E$2:$E$1001,$H26),"")) | F26: =IF($H26="","",IFERROR(INDEX(Personas!$F$2:$F$1001,$H26),"")) | G26: =IF($H26="","",IFERROR(INDEX(Personas!$G$2:$G$1001,$H26),"")) | H26: =IF($B$3="","",IFERROR(AGGREGATE(15,6,(ROW(Personas!$H$2:$H$1001)-ROW(Personas!$H$2)+1)/(ISNUMBER(SEARCH($B$3,Personas!$H$2:$H$1001))),20),""))
A27: =IF($H27="","",IFERROR(INDEX(Personas!$A$2:$A$1001,$H27),"")) | B27: =IF($H27="","",IFERROR(INDEX(Personas!$B$2:$B$1001,$H27),"")) | C27: =IF($H27="","",IFERROR(INDEX(Personas!$C$2:$C$1001,$H27),"")) | D27: =IF($H27="","",IFERROR(INDEX(Personas!$D$2:$D$1001,$H27),"")) | E27: =IF($H27="","",IFERROR(INDEX(Personas!$E$2:$E$1001,$H27),"")) | F27: =IF($H27="","",IFERROR(INDEX(Personas!$F$2:$F$1001,$H27),"")) | G27: =IF($H27="","",IFERROR(INDEX(Personas!$G$2:$G$1001,$H27),"")) | H27: =IF($B$3="","",IFERROR(AGGREGATE(15,6,(ROW(Personas!$H$2:$H$1001)-ROW(Personas!$H$2)+1)/(ISNUMBER(SEARCH($B$3,Personas!$H$2:$H$1001))),21),""))
A28: =IF($H28="","",IFERROR(INDEX(Personas!$A$2:$A$1001,$H28),"")) | B28: =IF($H28="","",IFERROR(INDEX(Personas!$B$2:$B$1001,$H28),"")) | C28: =IF($H28="","",IFERROR(INDEX(Personas!$C$2:$C$1001,$H28),"")) | D28: =IF($H28="","",IFERROR(INDEX(Personas!$D$2:$D$1001,$H28),"")) | E28: =IF($H28="","",IFERROR(INDEX(Personas!$E$2:$E$1001,$H28),"")) | F28: =IF($H28="","",IFERROR(INDEX(Personas!$F$2:$F$1001,$H28),"")) | G28: =IF($H28="","",IFERROR(INDEX(Personas!$G$2:$G$1001,$H28),"")) | H28: =IF($B$3="","",IFERROR(AGGREGATE(15,6,(ROW(Personas!$H$2:$H$1001)-ROW(Personas!$H$2)+1)/(ISNUMBER(SEARCH($B$3,Personas!$H$2:$H$1001))),22),""))
A29: =IF($H29="","",IFERROR(INDEX(Personas!$A$2:$A$1001,$H29),"")) | B29: =IF($H29="","",IFERROR(INDEX(Personas!$B$2:$B$1001,$H29),"")) | C29: =IF($H29="","",IFERROR(INDEX(Personas!$C$2:$C$1001,$H29),"")) | D29: =IF($H29="","",IFERROR(INDEX(Personas!$D$2:$D$1001,$H29),"")) | E29: =IF($H29="","",IFERROR(INDEX(Personas!$E$2:$E$1001,$H29),"")) | F29: =IF($H29="","",IFERROR(INDEX(Personas!$F$2:$F$1001,$H29),"")) | G29: =IF($H29="","",IFERROR(INDEX(Personas!$G$2:$G$1001,$H29),"")) | H29: =IF($B$3="","",IFERROR(AGGREGATE(15,6,(ROW(Personas!$H$2:$H$1001)-ROW(Personas!$H$2)+1)/(ISNUMBER(SEARCH($B$3,Personas!$H$2:$H$1001))),23),""))
A30: =IF($H30="","",IFERROR(INDEX(Personas!$A$2:$A$1001,$H30),"")) | B30: =IF($H30="","",IFERROR(INDEX(Personas!$B$2:$B$1001,$H30),"")) | C30: =IF($H30="","",IFERROR(INDEX(Personas!$C$2:$C$1001,$H30),"")) | D30: =IF($H30="","",IFERROR(INDEX(Personas!$D$2:$D$1001,$H30),"")) | E30: =IF($H30="","",IFERROR(INDEX(Personas!$E$2:$E$1001,$H30),"")) | F30: =IF($H30="","",IFERROR(INDEX(Personas!$F$2:$F$1001,$H30),"")) | G30: =IF($H30="","",IFERROR(INDEX(Personas!$G$2:$G$1001,$H30),"")) | H30: =IF($B$3="","",IFERROR(AGGREGATE(15,6,(ROW(Personas!$H$2:$H$1001)-ROW(Personas!$H$2)+1)/(ISNUMBER(SEARCH($B$3,Personas!$H$2:$H$1001))),24),""))
A31: =IF($H31="","",IFERROR(INDEX(Personas!$A$2:$A$1001,$H31),"")) | B31: =IF($H31="","",IFERROR(INDEX(Personas!$B$2:$B$1001,$H31),"")) | C31: =IF($H31="","",IFERROR(INDEX(Personas!$C$2:$C$1001,$H31),"")) | D31: =IF($H31="","",IFERROR(INDEX(Personas!$D$2:$D$1001,$H31),"")) | E31: =IF($H31="","",IFERROR(INDEX(Personas!$E$2:$E$1001,$H31),"")) | F31: =IF($H31="","",IFERROR(INDEX(Personas!$F$2:$F$1001,$H31),"")) | G31: =IF($H31="","",IFERROR(INDEX(Personas!$G$2:$G$1001,$H31),"")) | H31: =IF($B$3="","",IFERROR(AGGREGATE(15,6,(ROW(Personas!$H$2:$H$1001)-ROW(Personas!$H$2)+1)/(ISNUMBER(SEARCH($B$3,Personas!$H$2:$H$1001))),25),""))
A32: =IF($H32="","",IFERROR(INDEX(Personas!$A$2:$A$1001,$H32),"")) | B32: =IF($H32="","",IFERROR(INDEX(Personas!$B$2:$B$1001,$H32),"")) | C32: =IF($H32="","",IFERROR(INDEX(Personas!$C$2:$C$1001,$H32),"")) | D32: =IF($H32="","",IFERROR(INDEX(Personas!$D$2:$D$1001,$H32),"")) | E32: =IF($H32="","",IFERROR(INDEX(Personas!$E$2:$E$1001,$H32),"")) | F32: =IF($H32="","",IFERROR(INDEX(Personas!$F$2:$F$1001,$H32),"")) | G32: =IF($H32="","",IFERROR(INDEX(Personas!$G$2:$G$1001,$H32),"")) | H32: =IF($B$3="","",IFERROR(AGGREGATE(15,6,(ROW(Personas!$H$2:$H$1001)-ROW(Personas!$H$2)+1)/(ISNUMBER(SEARCH($B$3,Personas!$H$2:$H$1001))),26),""))
A33: =IF($H33="","",IFERROR(INDEX(Personas!$A$2:$A$1001,$H33),"")) | B33: =IF($H33="","",IFERROR(INDEX(Personas!$B$2:$B$1001,$H33),"")) | C33: =IF($H33="","",IFERROR(INDEX(Personas!$C$2:$C$1001,$H33),"")) | D33: =IF($H33="","",IFERROR(INDEX(Personas!$D$2:$D$1001,$H33),"")) | E33: =IF($H33="","",IFERROR(INDEX(Personas!$E$2:$E$1001,$H33),"")) | F33: =IF($H33="","",IFERROR(INDEX(Personas!$F$2:$F$1001,$H33),"")) | G33: =IF($H33="","",IFERROR(INDEX(Personas!$G$2:$G$1001,$H33),"")) | H33: =IF($B$3="","",IFERROR(AGGREGATE(15,6,(ROW(Personas!$H$2:$H$1001)-ROW(Personas!$H$2)+1)/(ISNUMBER(SEARCH($B$3,Personas!$H$2:$H$1001))),27),""))
A34: =IF($H34="","",IFERROR(INDEX(Personas!$A$2:$A$1001,$H34),"")) | B34: =IF($H34="","",IFERROR(INDEX(Personas!$B$2:$B$1001,$H34),"")) | C34: =IF($H34="","",IFERROR(INDEX(Personas!$C$2:$C$1001,$H34),"")) | D34: =IF($H34="","",IFERROR(INDEX(Personas!$D$2:$D$1001,$H34),"")) | E34: =IF($H34="","",IFERROR(INDEX(Personas!$E$2:$E$1001,$H34),"")) | F34: =IF($H34="","",IFERROR(INDEX(Personas!$F$2:$F$1001,$H34),"")) | G34: =IF($H34="","",IFERROR(INDEX(Personas!$G$2:$G$1001,$H34),"")) | H34: =IF($B$3="","",IFERROR(AGGREGATE(15,6,(ROW(Personas!$H$2:$H$1001)-ROW(Personas!$H$2)+1)/(ISNUMBER(SEARCH($B$3,Personas!$H$2:$H$1001))),28),""))
A35: =IF($H35="","",IFERROR(INDEX(Personas!$A$2:$A$1001,$H35),"")) | B35: =IF($H35="","",IFERROR(INDEX(Personas!$B$2:$B$1001,$H35),"")) | C35: =IF($H35="","",IFERROR(INDEX(Personas!$C$2:$C$1001,$H35),"")) | D35: =IF($H35="","",IFERROR(INDEX(Personas!$D$2:$D$1001,$H35),"")) | E35: =IF($H35="","",IFERROR(INDEX(Personas!$E$2:$E$1001,$H35),"")) | F35: =IF($H35="","",IFERROR(INDEX(Personas!$F$2:$F$1001,$H35),"")) | G35: =IF($H35="","",IFERROR(INDEX(Personas!$G$2:$G$1001,$H35),"")) | H35: =IF($B$3="","",IFERROR(AGGREGATE(15,6,(ROW(Personas!$H$2:$H$1001)-ROW(Personas!$H$2)+1)/(ISNUMBER(SEARCH($B$3,Personas!$H$2:$H$1001))),29),""))
A36: =IF($H36="","",IFERROR(INDEX(Personas!$A$2:$A$1001,$H36),"")) | B36: =IF($H36="","",IFERROR(INDEX(Personas!$B$2:$B$1001,$H36),"")) | C36: =IF($H36="","",IFERROR(INDEX(Personas!$C$2:$C$1001,$H36),"")) | D36: =IF($H36="","",IFERROR(INDEX(Personas!$D$2:$D$1001,$H36),"")) | E36: =IF($H36="","",IFERROR(INDEX(Personas!$E$2:$E$1001,$H36),"")) | F36: =IF($H36="","",IFERROR(INDEX(Personas!$F$2:$F$1001,$H36),"")) | G36: =IF($H36="","",IFERROR(INDEX(Personas!$G$2:$G$1001,$H36),"")) | H36: =IF($B$3="","",IFERROR(AGGREGATE(15,6,(ROW(Personas!$H$2:$H$1001)-ROW(Personas!$H$2)+1)/(ISNUMBER(SEARCH($B$3,Personas!$H$2:$H$1001))),30),""))
A37: =IF($H37="","",IFERROR(INDEX(Personas!$A$2:$A$1001,$H37),"")) | B37: =IF($H37="","",IFERROR(INDEX(Personas!$B$2:$B$1001,$H37),"")) | C37: =IF($H37="","",IFERROR(INDEX(Personas!$C$2:$C$1001,$H37),"")) | D37: =IF($H37="","",IFERROR(INDEX(Personas!$D$2:$D$1001,$H37),"")) | E37: =IF($H37="","",IFERROR(INDEX(Personas!$E$2:$E$1001,$H37),"")) | F37: =IF($H37="","",IFERROR(INDEX(Personas!$F$2:$F$1001,$H37),"")) | G37: =IF($H37="","",IFERROR(INDEX(Personas!$G$2:$G$1001,$H37),"")) | H37: =IF($B$3="","",IFERROR(AGGREGATE(15,6,(ROW(Personas!$H$2:$H$1001)-ROW(Personas!$H$2)+1)/(ISNUMBER(SEARCH($B$3,Personas!$H$2:$H$1001))),31),""))
A38: =IF($H38="","",IFERROR(INDEX(Personas!$A$2:$A$1001,$H38),"")) | B38: =IF($H38="","",IFERROR(INDEX(Personas!$B$2:$B$1001,$H38),"")) | C38: =IF($H38="","",IFERROR(INDEX(Personas!$C$2:$C$1001,$H38),"")) | D38: =IF($H38="","",IFERROR(INDEX(Personas!$D$2:$D$1001,$H38),"")) | E38: =IF($H38="","",IFERROR(INDEX(Personas!$E$2:$E$1001,$H38),"")) | F38: =IF($H38="","",IFERROR(INDEX(Personas!$F$2:$F$1001,$H38),"")) | G38: =IF($H38="","",IFERROR(INDEX(Personas!$G$2:$G$1001,$H38),"")) | H38: =IF($B$3="","",IFERROR(AGGREGATE(15,6,(ROW(Personas!$H$2:$H$1001)-ROW(Personas!$H$2)+1)/(ISNUMBER(SEARCH($B$3,Personas!$H$2:$H$1001))),32),""))
A39: =IF($H39="","",IFERROR(INDEX(Personas!$A$2:$A$1001,$H39),"")) | B39: =IF($H39="","",IFERROR(INDEX(Personas!$B$2:$B$1001,$H39),"")) | C39: =IF($H39="","",IFERROR(INDEX(Personas!$C$2:$C$1001,$H39),"")) | D39: =IF($H39="","",IFERROR(INDEX(Personas!$D$2:$D$1001,$H39),"")) | E39: =IF($H39="","",IFERROR(INDEX(Personas!$E$2:$E$1001,$H39),"")) | F39: =IF($H39="","",IFERROR(INDEX(Personas!$F$2:$F$1001,$H39),"")) | G39: =IF($H39="","",IFERROR(INDEX(Personas!$G$2:$G$1001,$H39),"")) | H39: =IF($B$3="","",IFERROR(AGGREGATE(15,6,(ROW(Personas!$H$2:$H$1001)-ROW(Personas!$H$2)+1)/(ISNUMBER(SEARCH($B$3,Personas!$H$2:$H$1001))),33),""))
A40: =IF($H40="","",IFERROR(INDEX(Personas!$A$2:$A$1001,$H40),"")) | B40: =IF($H40="","",IFERROR(INDEX(Personas!$B$2:$B$1001,$H40),"")) | C40: =IF($H40="","",IFERROR(INDEX(Personas!$C$2:$C$1001,$H40),"")) | D40: =IF($H40="","",IFERROR(INDEX(Personas!$D$2:$D$1001,$H40),"")) | E40: =IF($H40="","",IFERROR(INDEX(Personas!$E$2:$E$1001,$H40),"")) | F40: =IF($H40="","",IFERROR(INDEX(Personas!$F$2:$F$1001,$H40),"")) | G40: =IF($H40="","",IFERROR(INDEX(Personas!$G$2:$G$1001,$H40),"")) | H40: =IF($B$3="","",IFERROR(AGGREGATE(15,6,(ROW(Personas!$H$2:$H$1001)-ROW(Personas!$H$2)+1)/(ISNUMBER(SEARCH($B$3,Personas!$H$2:$H$1001))),34),""))
A41: =IF($H41="","",IFERROR(INDEX(Personas!$A$2:$A$1001,$H41),"")) | B41: =IF($H41="","",IFERROR(INDEX(Personas!$B$2:$B$1001,$H41),"")) | C41: =IF($H41="","",IFERROR(INDEX(Personas!$C$2:$C$1001,$H41),"")) | D41: =IF($H41="","",IFERROR(INDEX(Personas!$D$2:$D$1001,$H41),"")) | E41: =IF($H41="","",IFERROR(INDEX(Personas!$E$2:$E$1001,$H41),"")) | F41: =IF($H41="","",IFERROR(INDEX(Personas!$F$2:$F$1001,$H41),"")) | G41: =IF($H41="","",IFERROR(INDEX(Personas!$G$2:$G$1001,$H41),"")) | H41: =IF($B$3="","",IFERROR(AGGREGATE(15,6,(ROW(Personas!$H$2:$H$1001)-ROW(Personas!$H$2)+1)/(ISNUMBER(SEARCH($B$3,Personas!$H$2:$H$1001))),35),""))
...

Sheet Personas
A1: Nombre completo | B1: Lista / promotor | C1: Tipo de lista | D1: Estado | E1: Hora de ingreso | F1: Fecha de nacimiento | G1: Detalle | H1: Búsqueda
A2: Ana Gómez | B2: CINTIA DÍAZ | C2: Promotor | D2: Pendiente | G2: Lista de promotor | H2: Ana Gómez CINTIA DÍAZ Promotor
A3: Juan Pérez | B3: CUMPLEAÑOS - SOFÍA MARTÍNEZ | C3: Cumpleaños | D3: Pendiente | G3: Invitado/a de cumpleaños | H3: Juan Pérez CUMPLEAÑOS - SOFÍA MARTÍNEZ Cumpleaños
A4: Sofía Martínez | B4: CUMPLEAÑOS - SOFÍA MARTÍNEZ | C4: Cumpleaños | D4: Ingresó | E4: 01:15 | F4: 2000-08-01 | G4: Cumpleañero/a | H4: Sofía Martínez CUMPLEAÑOS - SOFÍA MARTÍNEZ Cumpleaños
A5: Luis Promo | B5: PROMOS | C5: PROMOS | D5: Pendiente | G5: Lista automática PROMOS | H5: Luis Promo PROMOS PROMOS
A6: María Común | B6: LISTA COMÚN | C6: Lista común | D6: Pendiente | G6: Lista común | H6: María Común LISTA COMÚN Lista común
